Workbook

Sheet Léeme
A1: Surveillance de campos maduros: planilla de referencia del curso (sesión 3).
A2: Fuente: Capítulo IV agrupado por yacimiento y formación, Secretaría de Energía (datos.energia.gob.ar, CC BY 4.0).
A3: Solo producción convencional. Np es la acumulada desde enero de 2006, cuando empieza la serie; los campos más viejos traen producción anterior.
A4: Ventana reciente: 2026-05 a 2026-07. Base: 2025-05 a 2026-04.
A5: Caudal = petróleo del mes / días del mes. Caída de petróleo: rojo si es de 15% o más, amarillo desde 5%.
A6: RAP = agua / petróleo en cada ventana. Rojo si sube 15% o más, amarillo desde 5%. El semáforo es el peor de los dos.
A7: Para sumar un mes: pegá las filas nuevas al final de la hoja Datos y cambiá la celda B1 de la hoja Resumen.

Sheet Resumen
A1: Último mes (AAAA-MM) | B1: 2026-07 | C1: índice | D1: =VALUE(LEFT(B1,4))*12+VALUE(RIGHT(B1,2))-1
A2: Ventana reciente | B2: =INT(($D$1-2)/12)&"-"&RIGHT("0"&(MOD($D$1-2,12)+1),2) | C2: a | D2: =B1
A3: Base | B3: =INT(($D$1-14)/12)&"-"&RIGHT("0"&(MOD($D$1-14,12)+1),2) | C3: a | D3: =INT(($D$1-3)/12)&"-"&RIGHT("0"&(MOD($D$1-3,12)+1),2)
A5: Campo | B5: Operadora | C5: Petróleo reciente (m³/d) | D5: Petróleo base (m³/d) | E5: Cambio petróleo | F5: RAP reciente | G5: RAP base | H5: Cambio RAP | I5: Np desde 2006 (m³) | J5: Semáforo | K5: Revisar dato
A6: El Corcobo Norte | B6: PLUSPETROL S.A. | C6: =SUMIFS(Datos!$F$2:$F$2079,Datos!$A$2:$A$2079,$A6,Datos!$D$2:$D$2079,"convencional",Datos!$J$2:$J$2079,">="&($D$1-2),Datos!$J$2:$J$2079,"<="&$D$1)/SUMIFS(Datos!$I$2:$I$2079,Datos!$A$2:$A$2079,$A6,Datos!$D$2:$D$2079,"convencional",Datos!$J$2:$J$2079,">="&($D$1-2),Datos!$J$2:$J$2079,"<="&$D$1) | D6: =SUMIFS(Datos!$F$2:$F$2079,Datos!$A$2:$A$2079,$A6,Datos!$D$2:$D$2079,"convencional",Datos!$J$2:$J$2079,">="&($D$1-14),Datos!$J$2:$J$2079,"<="&($D$1-3))/SUMIFS(Datos!$I$2:$I$2079,Datos!$A$2:$A$2079,$A6,Datos!$D$2:$D$2079,"convencional",Datos!$J$2:$J$2079,">="&($D$1-14),Datos!$J$2:$J$2079,"<="&($D$1-3)) | E6: =C6/D6-1 | F6: =SUMIFS(Datos!$G$2:$G$2079,Datos!$A$2:$A$2079,$A6,Datos!$D$2:$D$2079,"convencional",Datos!$J$2:$J$2079,">="&($D$1-2),Datos!$J$2:$J$2079,"<="&$D$1)/SUMIFS(Datos!$F$2:$F$2079,Datos!$A$2:$A$2079,$A6,Datos!$D$2:$D$2079,"convencional",Datos!$J$2:$J$2079,">="&($D$1-2),Datos!$J$2:$J$2079,"<="&$D$1) | G6: =SUMIFS(Datos!$G$2:$G$2079,Datos!$A$2:$A$2079,$A6,Datos!$D$2:$D$2079,"convencional",Datos!$J$2:$J$2079,">="&($D$1-14),Datos!$J$2:$J$2079,"<="&($D$1-3))/SUMIFS(Datos!$F$2:$F$2079,Datos!$A$2:$A$2079,$A6,Datos!$D$2:$D$2079,"convencional",Datos!$J$2:$J$2079,">="&($D$1-14),Datos!$J$2:$J$2079,"<="&($D$1-3)) | H6: =F6/G6-1 | I6: =SUMIFS(Datos!$F$2:$F$2079,Datos!$A$2:$A$2079,$A6,Datos!$D$2:$D$2079,"convencional",Datos!$J$2:$J$2079,"<="&$D$1) | J6: =IF(OR(E6<=-0.15,H6>=0.15),"rojo",IF(OR(E6<=-0.05,H6>=0.05),"amarillo","verde")) | K6: falta 2019-01
A7: Chihuido de la Sierra Negra | B7: YPF S.A. | C7: =SUMIFS(Datos!$F$2:$F$2079,Datos!$A$2:$A$2079,$A7,Datos!$D$2:$D$2079,"convencional",Datos!$J$2:$J$2079,">="&($D$1-2),Datos!$J$2:$J$2079,"<="&$D$1)/SUMIFS(Datos!$I$2:$I$2079,Datos!$A$2:$A$2079,$A7,Datos!$D$2:$D$2079,"convencional",Datos!$J$2:$J$2079,">="&($D$1-2),Datos!$J$2:$J$2079,"<="&$D$1) | D7: =SUMIFS(Datos!$F$2:$F$2079,Datos!$A$2:$A$2079,$A7,Datos!$D$2:$D$2079,"convencional",Datos!$J$2:$J$2079,">="&($D$1-14),Datos!$J$2:$J$2079,"<="&($D$1-3))/SUMIFS(Datos!$I$2:$I$2079,Datos!$A$2:$A$2079,$A7,Datos!$D$2:$D$2079,"convencional",Datos!$J$2:$J$2079,">="&($D$1-14),Datos!$J$2:$J$2079,"<="&($D$1-3)) | E7: =C7/D7-1 | F7: =SUMIFS(Datos!$G$2:$G$2079,Datos!$A$2:$A$2079,$A7,Datos!$D$2:$D$2079,"convencional",Datos!$J$2:$J$2079,">="&($D$1-2),Datos!$J$2:$J$2079,"<="&$D$1)/SUMIFS(Datos!$F$2:$F$2079,Datos!$A$2:$A$2079,$A7,Datos!$D$2:$D$2079,"convencional",Datos!$J$2:$J$2079,">="&($D$1-2),Datos!$J$2:$J$2079,"<="&$D$1) | G7: =SUMIFS(Datos!$G$2:$G$2079,Datos!$A$2:$A$2079,$A7,Datos!$D$2:$D$2079,"convencional",Datos!$J$2:$J$2079,">="&($D$1-14),Datos!$J$2:$J$2079,"<="&($D$1-3))/SUMIFS(Datos!$F$2:$F$2079,Datos!$A$2:$A$2079,$A7,Datos!$D$2:$D$2079,"convencional",Datos!$J$2:$J$2079,">="&($D$1-14),Datos!$J$2:$J$2079,"<="&($D$1-3)) | H7: =F7/G7-1 | I7: =SUMIFS(Datos!$F$2:$F$2079,Datos!$A$2:$A$2079,$A7,Datos!$D$2:$D$2079,"convencional",Datos!$J$2:$J$2079,"<="&$D$1) | J7: =IF(OR(E7<=-0.15,H7>=0.15),"rojo",IF(OR(E7<=-0.05,H7>=0.05),"amarillo","verde"))
A8: El Trapial | B8: CHEVRON ARGENTINA S.R.L. | C8: =SUMIFS(Datos!$F$2:$F$2079,Datos!$A$2:$A$2079,$A8,Datos!$D$2:$D$2079,"convencional",Datos!$J$2:$J$2079,">="&($D$1-2),Datos!$J$2:$J$2079,"<="&$D$1)/SUMIFS(Datos!$I$2:$I$2079,Datos!$A$2:$A$2079,$A8,Datos!$D$2:$D$2079,"convencional",Datos!$J$2:$J$2079,">="&($D$1-2),Datos!$J$2:$J$2079,"<="&$D$1) | D8: =SUMIFS(Datos!$F$2:$F$2079,Datos!$A$2:$A$2079,$A8,Datos!$D$2:$D$2079,"convencional",Datos!$J$2:$J$2079,">="&($D$1-14),Datos!$J$2:$J$2079,"<="&($D$1-3))/SUMIFS(Datos!$I$2:$I$2079,Datos!$A$2:$A$2079,$A8,Datos!$D$2:$D$2079,"convencional",Datos!$J$2:$J$2079,">="&($D$1-14),Datos!$J$2:$J$2079,"<="&($D$1-3)) | E8: =C8/D8-1 | F8: =SUMIFS(Datos!$G$2:$G$2079,Datos!$A$2:$A$2079,$A8,Datos!$D$2:$D$2079,"convencional",Datos!$J$2:$J$2079,">="&($D$1-2),Datos!$J$2:$J$2079,"<="&$D$1)/SUMIFS(Datos!$F$2:$F$2079,Datos!$A$2:$A$2079,$A8,Datos!$D$2:$D$2079,"convencional",Datos!$J$2:$J$2079,">="&($D$1-2),Datos!$J$2:$J$2079,"<="&$D$1) | G8: =SUMIFS(Datos!$G$2:$G$2079,Datos!$A$2:$A$2079,$A8,Datos!$D$2:$D$2079,"convencional",Datos!$J$2:$J$2079,">="&($D$1-14),Datos!$J$2:$J$2079,"<="&($D$1-3))/SUMIFS(Datos!$F$2:$F$2079,Datos!$A$2:$A$2079,$A8,Datos!$D$2:$D$2079,"convencional",Datos!$J$2:$J$2079,">="&($D$1-14),Datos!$J$2:$J$2079,"<="&($D$1-3)) | H8: =F8/G8-1 | I8: =SUMIFS(Datos!$F$2:$F$2079,Datos!$A$2:$A$2079,$A8,Datos!$D$2:$D$2079,"convencional",Datos!$J$2:$J$2079,"<="&$D$1) | J8: =IF(OR(E8<=-0.15,H8>=0.15),"rojo",IF(OR(E8<=-0.05,H8>=0.05),"amarillo","verde"))
A9: Puesto Hernández | B9: YPF S.A. | C9: =SUMIFS(Datos!$F$2:$F$2079,Datos!$A$2:$A$2079,$A9,Datos!$D$2:$D$2079,"convencional",Datos!$J$2:$J$2079,">="&($D$1-2),Datos!$J$2:$J$2079,"<="&$D$1)/SUMIFS(Datos!$I$2:$I$2079,Datos!$A$2:$A$2079,$A9,Datos!$D$2:$D$2079,"convencional",Datos!$J$2:$J$2079,">="&($D$1-2),Datos!$J$2:$J$2079,"<="&$D$1) | D9: =SUMIFS(Datos!$F$2:$F$2079,Datos!$A$2:$A$2079,$A9,Datos!$D$2:$D$2079,"convencional",Datos!$J$2:$J$2079,">="&($D$1-14),Datos!$J$2:$J$2079,"<="&($D$1-3))/SUMIFS(Datos!$I$2:$I$2079,Datos!$A$2:$A$2079,$A9,Datos!$D$2:$D$2079,"convencional",Datos!$J$2:$J$2079,">="&($D$1-14),Datos!$J$2:$J$2079,"<="&($D$1-3)) | E9: =C9/D9-1 | F9: =SUMIFS(Datos!$G$2:$G$2079,Datos!$A$2:$A$2079,$A9,Datos!$D$2:$D$2079,"convencional",Datos!$J$2:$J$2079,">="&($D$1-2),Datos!$J$2:$J$2079,"<="&$D$1)/SUMIFS(Datos!$F$2:$F$2079,Datos!$A$2:$A$2079,$A9,Datos!$D$2:$D$2079,"convencional",Datos!$J$2:$J$2079,">="&($D$1-2),Datos!$J$2:$J$2079,"<="&$D$1) | G9: =SUMIFS(Datos!$G$2:$G$2079,Datos!$A$2:$A$2079,$A9,Datos!$D$2:$D$2079,"convencional",Datos!$J$2:$J$2079,">="&($D$1-14),Datos!$J$2:$J$2079,"<="&($D$1-3))/SUMIFS(Datos!$F$2:$F$2079,Datos!$A$2:$A$2079,$A9,Datos!$D$2:$D$2079,"convencional",Datos!$J$2:$J$2079,">="&($D$1-14),Datos!$J$2:$J$2079,"<="&($D$1-3)) | H9: =F9/G9-1 | I9: =SUMIFS(Datos!$F$2:$F$2079,Datos!$A$2:$A$2079,$A9,Datos!$D$2:$D$2079,"convencional",Datos!$J$2:$J$2079,"<="&$D$1) | J9: =IF(OR(E9<=-0.15,H9>=0.15),"rojo",IF(OR(E9<=-0.05,H9>=0.05),"amarillo","verde"))
A10: Los Perales | B10: PATAGONIA RESOURCES S.A. | C10: =SUMIFS(Datos!$F$2:$F$2079,Datos!$A$2:$A$2079,$A10,Datos!$D$2:$D$2079,"convencional",Datos!$J$2:$J$2079,">="&($D$1-2),Datos!$J$2:$J$2079,"<="&$D$1)/SUMIFS(Datos!$I$2:$I$2079,Datos!$A$2:$A$2079,$A10,Datos!$D$2:$D$2079,"convencional",Datos!$J$2:$J$2079,">="&($D$1-2),Datos!$J$2:$J$2079,"<="&$D$1) | D10: =SUMIFS(Datos!$F$2:$F$2079,Datos!$A$2:$A$2079,$A10,Datos!$D$2:$D$2079,"convencional",Datos!$J$2:$J$2079,">="&($D$1-14),Datos!$J$2:$J$2079,"<="&($D$1-3))/SUMIFS(Datos!$I$2:$I$2079,Datos!$A$2:$A$2079,$A10,Datos!$D$2:$D$2079,"convencional",Datos!$J$2:$J$2079,">="&($D$1-14),Datos!$J$2:$J$2079,"<="&($D$1-3)) | E10: =C10/D10-1 | F10: =SUMIFS(Datos!$G$2:$G$2079,Datos!$A$2:$A$2079,$A10,Datos!$D$2:$D$2079,"convencional",Datos!$J$2:$J$2079,">="&($D$1-2),Datos!$J$2:$J$2079,"<="&$D$1)/SUMIFS(Datos!$F$2:$F$2079,Datos!$A$2:$A$2079,$A10,Datos!$D$2:$D$2079,"convencional",Datos!$J$2:$J$2079,">="&($D$1-2),Datos!$J$2:$J$2079,"<="&$D$1) | G10: =SUMIFS(Datos!$G$2:$G$2079,Datos!$A$2:$A$2079,$A10,Datos!$D$2:$D$2079,"convencional",Datos!$J$2:$J$2079,">="&($D$1-14),Datos!$J$2:$J$2079,"<="&($D$1-3))/SUMIFS(Datos!$F$2:$F$2079,Datos!$A$2:$A$2079,$A10,Datos!$D$2:$D$2079,"convencional",Datos!$J$2:$J$2079,">="&($D$1-14),Datos!$J$2:$J$2079,"<="&($D$1-3)) | H10: =F10/G10-1 | I10: =SUMIFS(Datos!$F$2:$F$2079,Datos!$A$2:$A$2079,$A10,Datos!$D$2:$D$2079,"convencional",Datos!$J$2:$J$2079,"<="&$D$1) | J10: =IF(OR(E10<=-0.15,H10>=0.15),"rojo",IF(OR(E10<=-0.05,H10>=0.05),"amarillo","verde")) | K10: cambió de operadora: YPF S.A. → PATAGONIA RESOURCES S.A.
A11: Manantiales Behr | B11: PECOM SERVICIOS ENERGIA SAU | C11: =SUMIFS(Datos!$F$2:$F$2079,Datos!$A$2:$A$2079,$A11,Datos!$D$2:$D$2079,"convencional",Datos!$J$2:$J$2079,">="&($D$1-2),Datos!$J$2:$J$2079,"<="&$D$1)/SUMIFS(Datos!$I$2:$I$2079,Datos!$A$2:$A$2079,$A11,Datos!$D$2:$D$2079,"convencional",Datos!$J$2:$J$2079,">="&($D$1-2),Datos!$J$2:$J$2079,"<="&$D$1) | D11: =SUMIFS(Datos!$F$2:$F$2079,Datos!$A$2:$A$2079,$A11,Datos!$D$2:$D$2079,"convencional",Datos!$J$2:$J$2079,">="&($D$1-14),Datos!$J$2:$J$2079,"<="&($D$1-3))/SUMIFS(Datos!$I$2:$I$2079,Datos!$A$2:$A$2079,$A11,Datos!$D$2:$D$2079,"convencional",Datos!$J$2:$J$2079,">="&($D$1-14),Datos!$J$2:$J$2079,"<="&($D$1-3)) | E11: =C11/D11-1 | F11: =SUMIFS(Datos!$G$2:$G$2079,Datos!$A$2:$A$2079,$A11,Datos!$D$2:$D$2079,"convencional",Datos!$J$2:$J$2079,">="&($D$1-2),Datos!$J$2:$J$2079,"<="&$D$1)/SUMIFS(Datos!$F$2:$F$2079,Datos!$A$2:$A$2079,$A11,Datos!$D$2:$D$2079,"convencional",Datos!$J$2:$J$2079,">="&($D$1-2),Datos!$J$2:$J$2079,"<="&$D$1) | G11: =SUMIFS(Datos!$G$2:$G$2079,Datos!$A$2:$A$2079,$A11,Datos!$D$2:$D$2079,"convencional",Datos!$J$2:$J$2079,">="&($D$1-14),Datos!$J$2:$J$2079,"<="&($D$1-3))/SUMIFS(Datos!$F$2:$F$2079,Datos!$A$2:$A$2079,$A11,Datos!$D$2:$D$2079,"convencional",Datos!$J$2:$J$2079,">="&($D$1-14),Datos!$J$2:$J$2079,"<="&($D$1-3)) | H11: =F11/G11-1 | I11: =SUMIFS(Datos!$F$2:$F$2079,Datos!$A$2:$A$2079,$A11,Datos!$D$2:$D$2079,"convencional",Datos!$J$2:$J$2079,"<="&$D$1) | J11: =IF(OR(E11<=-0.15,H11>=0.15),"rojo",IF(OR(E11<=-0.05,H11>=0.05),"amarillo","verde")) | K11: cambió de operadora: YPF S.A. → PECOM SERVICIOS ENERGIA SAU
A12: Diadema | B12: COMPAÑÍAS ASOCIADAS PETROLERAS S.A. | C12: =SUMIFS(Datos!$F$2:$F$2079,Datos!$A$2:$A$2079,$A12,Datos!$D$2:$D$2079,"convencional",Datos!$J$2:$J$2079,">="&($D$1-2),Datos!$J$2:$J$2079,"<="&$D$1)/SUMIFS(Datos!$I$2:$I$2079,Datos!$A$2:$A$2079,$A12,Datos!$D$2:$D$2079,"convencional",Datos!$J$2:$J$2079,">="&($D$1-2),Datos!$J$2:$J$2079,"<="&$D$1) | D12: =SUMIFS(Datos!$F$2:$F$2079,Datos!$A$2:$A$2079,$A12,Datos!$D$2:$D$2079,"convencional",Datos!$J$2:$J$2079,">="&($D$1-14),Datos!$J$2:$J$2079,"<="&($D$1-3))/SUMIFS(Datos!$I$2:$I$2079,Datos!$A$2:$A$2079,$A12,Datos!$D$2:$D$2079,"convencional",Datos!$J$2:$J$2079,">="&($D$1-14),Datos!$J$2:$J$2079,"<="&($D$1-3)) | E12: =C12/D12-1 | F12: =SUMIFS(Datos!$G$2:$G$2079,Datos!$A$2:$A$2079,$A12,Datos!$D$2:$D$2079,"convencional",Datos!$J$2:$J$2079,">="&($D$1-2),Datos!$J$2:$J$2079,"<="&$D$1)/SUMIFS(Datos!$F$2:$F$2079,Datos!$A$2:$A$2079,$A12,Datos!$D$2:$D$2079,"convencional",Datos!$J$2:$J$2079,">="&($D$1-2),Datos!$J$2:$J$2079,"<="&$D$1) | G12: =SUMIFS(Datos!$G$2:$G$2079,Datos!$A$2:$A$2079,$A12,Datos!$D$2:$D$2079,"convencional",Datos!$J$2:$J$2079,">="&($D$1-14),Datos!$J$2:$J$2079,"<="&($D$1-3))/SUMIFS(Datos!$F$2:$F$2079,Datos!$A$2:$A$2079,$A12,Datos!$D$2:$D$2079,"convencional",Datos!$J$2:$J$2079,">="&($D$1-14),Datos!$J$2:$J$2079,"<="&($D$1-3)) | H12: =F12/G12-1 | I12: =SUMIFS(Datos!$F$2:$F$2079,Datos!$A$2:$A$2079,$A12,Datos!$D$2:$D$2079,"convencional",Datos!$J$2:$J$2079,"<="&$D$1) | J12: =IF(OR(E12<=-0.15,H12>=0.15),"rojo",IF(OR(E12<=-0.05,H12>=0.05),"amarillo","verde"))

Sheet Datos
A1: campo | B1: cuenca | C1: operadora | D1: tipo_recurso | E1: mes | F1: petroleo_m3 | G1: agua_m3 | H1: iny_agua_m3 | I1: dias | J1: idx
A2: El Corcobo Norte | B2: Neuquina | C2: PETRO ANDINA RESOURCES LTD. | D2: convencional | E2: 2006-01 | F2: 503.2 | G2: 2 | H2: 0 | I2: =DAY(EOMONTH(DATE(VALUE(LEFT(E2,4)),VALUE(RIGHT(E2,2)),1),0)) | J2: =VALUE(LEFT(E2,4))*12+VALUE(RIGHT(E2,2))-1
A3: El Corcobo Norte | B3: Neuquina | C3: PETRO ANDINA RESOURCES LTD. | D3: convencional | E3: 2006-02 | F3: 1388.5 | G3: 58.5 | H3: 0 | I3: =DAY(EOMONTH(DATE(VALUE(LEFT(E3,4)),VALUE(RIGHT(E3,2)),1),0)) | J3: =VALUE(LEFT(E3,4))*12+VALUE(RIGHT(E3,2))-1
A4: El Corcobo Norte | B4: Neuquina | C4: PETRO ANDINA RESOURCES LTD. | D4: convencional | E4: 2006-03 | F4: 2164.3 | G4: 55.6 | H4: 0 | I4: =DAY(EOMONTH(DATE(VALUE(LEFT(E4,4)),VALUE(RIGHT(E4,2)),1),0)) | J4: =VALUE(LEFT(E4,4))*12+VALUE(RIGHT(E4,2))-1
A5: El Corcobo Norte | B5: Neuquina | C5: PETRO ANDINA RESOURCES LTD. | D5: convencional | E5: 2006-04 | F5: 3353.8 | G5: 141.3 | H5: 0 | I5: =DAY(EOMONTH(DATE(VALUE(LEFT(E5,4)),VALUE(RIGHT(E5,2)),1),0)) | J5: =VALUE(LEFT(E5,4))*12+VALUE(RIGHT(E5,2))-1
A6: El Corcobo Norte | B6: Neuquina | C6: PETRO ANDINA RESOURCES LTD. | D6: convencional | E6: 2006-05 | F6: 4083.4 | G6: 499.8 | H6: 0 | I6: =DAY(EOMONTH(DATE(VALUE(LEFT(E6,4)),VALUE(RIGHT(E6,2)),1),0)) | J6: =VALUE(LEFT(E6,4))*12+VALUE(RIGHT(E6,2))-1
A7: El Corcobo Norte | B7: Neuquina | C7: PETRO ANDINA RESOURCES LTD. | D7: convencional | E7: 2006-06 | F7: 4941.3 | G7: 723.6 | H7: 0 | I7: =DAY(EOMONTH(DATE(VALUE(LEFT(E7,4)),VALUE(RIGHT(E7,2)),1),0)) | J7: =VALUE(LEFT(E7,4))*12+VALUE(RIGHT(E7,2))-1
A8: El Corcobo Norte | B8: Neuquina | C8: PETRO ANDINA RESOURCES LTD. | D8: convencional | E8: 2006-07 | F8: 5047.2 | G8: 1201.8 | H8: 0 | I8: =DAY(EOMONTH(DATE(VALUE(LEFT(E8,4)),VALUE(RIGHT(E8,2)),1),0)) | J8: =VALUE(LEFT(E8,4))*12+VALUE(RIGHT(E8,2))-1
A9: El Corcobo Norte | B9: Neuquina | C9: PETRO ANDINA RESOURCES LTD. | D9: convencional | E9: 2006-08 | F9: 6348.8 | G9: 1859.8 | H9: 0 | I9: =DAY(EOMONTH(DATE(VALUE(LEFT(E9,4)),VALUE(RIGHT(E9,2)),1),0)) | J9: =VALUE(LEFT(E9,4))*12+VALUE(RIGHT(E9,2))-1
A10: El Corcobo Norte | B10: Neuquina | C10: PETRO ANDINA RESOURCES LTD. | D10: convencional | E10: 2006-09 | F10: 10565.3 | G10: 2794.3 | H10: 0 | I10: =DAY(EOMONTH(DATE(VALUE(LEFT(E10,4)),VALUE(RIGHT(E10,2)),1),0)) | J10: =VALUE(LEFT(E10,4))*12+VALUE(RIGHT(E10,2))-1
A11: El Corcobo Norte | B11: Neuquina | C11: PETRO ANDINA RESOURCES LTD. | D11: convencional | E11: 2006-10 | F11: 17676.7 | G11: 4473.8 | H11: 0 | I11: =DAY(EOMONTH(DATE(VALUE(LEFT(E11,4)),VALUE(RIGHT(E11,2)),1),0)) | J11: =VALUE(LEFT(E11,4))*12+VALUE(RIGHT(E11,2))-1
A12: El Corcobo Norte | B12: Neuquina | C12: PETRO ANDINA RESOURCES LTD. | D12: convencional | E12: 2006-11 | F12: 18485 | G12: 7762.6 | H12: 0 | I12: =DAY(EOMONTH(DATE(VALUE(LEFT(E12,4)),VALUE(RIGHT(E12,2)),1),0)) | J12: =VALUE(LEFT(E12,4))*12+VALUE(RIGHT(E12,2))-1
A13: El Corcobo Norte | B13: Neuquina | C13: PETRO ANDINA RESOURCES LTD. | D13: convencional | E13: 2006-12 | F13: 20180.1 | G13: 8352.7 | H13: 0 | I13: =DAY(EOMONTH(DATE(VALUE(LEFT(E13,4)),VALUE(RIGHT(E13,2)),1),0)) | J13: =VALUE(LEFT(E13,4))*12+VALUE(RIGHT(E13,2))-1
... A2079: Diadema | B2079: Golfo San Jorge | C2079: COMPAÑÍAS ASOCIADAS PETROLERAS S.A. | D2079: convencional | E2079: 2026-07 | F2079: 49306.7 | G2079: 1353576.4 | H2079: 1351263.9 | I2079: =DAY(EOMONTH(DATE(VALUE(LEFT(E2079,4)),VALUE(RIGHT(E2079,2)),1),0)) | J2079: =VALUE(LEFT(E2079,4))*12+VALUE(RIGHT(E2079,2))-1

Sheet RAP vs Np
A1: Campo | B1: Mes | C1: Petróleo (m³) | D1: Agua (m³) | E1: Np desde 2006 (m³) | F1: RAP
A2: El Corcobo Norte | B2: 2006-01 | C2: 503.2 | D2: 2 | E2: =C2 | F2: =IF(C2>0,D2/C2,NA())
A3: El Corcobo Norte | B3: 2006-02 | C3: 1388.5 | D3: 58.5 | E3: =E2+C3 | F3: =IF(C3>0,D3/C3,NA())
A4: El Corcobo Norte | B4: 2006-03 | C4: 2164.3 | D4: 55.6 | E4: =E3+C4 | F4: =IF(C4>0,D4/C4,NA())
A5: El Corcobo Norte | B5: 2006-04 | C5: 3353.8 | D5: 141.3 | E5: =E4+C5 | F5: =IF(C5>0,D5/C5,NA())
A6: El Corcobo Norte | B6: 2006-05 | C6: 4083.4 | D6: 499.8 | E6: =E5+C6 | F6: =IF(C6>0,D6/C6,NA())
A7: El Corcobo Norte | B7: 2006-06 | C7: 4941.3 | D7: 723.6 | E7: =E6+C7 | F7: =IF(C7>0,D7/C7,NA())
A8: El Corcobo Norte | B8: 2006-07 | C8: 5047.2 | D8: 1201.8 | E8: =E7+C8 | F8: =IF(C8>0,D8/C8,NA())
A9: El Corcobo Norte | B9: 2006-08 | C9: 6348.8 | D9: 1859.8 | E9: =E8+C9 | F9: =IF(C9>0,D9/C9,NA())
A10: El Corcobo Norte | B10: 2006-09 | C10: 10565.3 | D10: 2794.3 | E10: =E9+C10 | F10: =IF(C10>0,D10/C10,NA())
A11: El Corcobo Norte | B11: 2006-10 | C11: 17676.7 | D11: 4473.8 | E11: =E10+C11 | F11: =IF(C11>0,D11/C11,NA())
A12: El Corcobo Norte | B12: 2006-11 | C12: 18485 | D12: 7762.6 | E12: =E11+C12 | F12: =IF(C12>0,D12/C12,NA())
A13: El Corcobo Norte | B13: 2006-12 | C13: 20180.1 | D13: 8352.7 | E13: =E12+C13 | F13: =IF(C13>0,D13/C13,NA())
A14: El Corcobo Norte | B14: 2007-01 | C14: 21859.2 | D14: 8607.3 | E14: =E13+C14 | F14: =IF(C14>0,D14/C14,NA())
... A247: El Corcobo Norte | B247: 2026-07 | C247: 38246.2 | D247: 678885.8 | E247: =E246+C247 | F247: =IF(C247>0,D247/C247,NA())
A248: Chihuido de la Sierra Negra | B248: 2006-01 | C248: 111100.5 | D248: 1275854.7 | E248: =C248 | F248: =IF(C248>0,D248/C248,NA())
A249: Chihuido de la Sierra Negra | B249: 2006-02 | C249: 97685.5 | D249: 1126539.1 | E249: =E248+C249 | F249: =IF(C249>0,D249/C249,NA())
A250: Chihuido de la Sierra Negra | B250: 2006-03 | C250: 102277.4 | D250: 1161147.4 | E250: =E249+C250 | F250: =IF(C250>0,D250/C250,NA())
A251: Chihuido de la Sierra Negra | B251: 2006-04 | C251: 96939.1 | D251: 1042168.2 | E251: =E250+C251 | F251: =IF(C251>0,D251/C251,NA())
A252: Chihuido de la Sierra Negra | B252: 2006-05 | C252: 103819.4 | D252: 1216110.1 | E252: =E251+C252 | F252: =IF(C252>0,D252/C252,NA())
A253: Chihuido de la Sierra Negra | B253: 2006-06 | C253: 99959.9 | D253: 1203809.6 | E253: =E252+C253 | F253: =IF(C253>0,D253/C253,NA())
A254: Chihuido de la Sierra Negra | B254: 2006-07 | C254: 100927.2 | D254: 1231473.6 | E254: =E253+C254 | F254: =IF(C254>0,D254/C254,NA())
A255: Chihuido de la Sierra Negra | B255: 2006-08 | C255: 98666 | D255: 1211460.4 | E255: =E254+C255 | F255: =IF(C255>0,D255/C255,NA())
A256: Chihuido de la Sierra Negra | B256: 2006-09 | C256: 95417.5 | D256: 1165300.2 | E256: =E255+C256 | F256: =IF(C256>0,D256/C256,NA())
A257: Chihuido de la Sierra Negra | B257: 2006-10 | C257: 97038.7 | D257: 1202259.1 | E257: =E256+C257 | F257: =IF(C257>0,D257/C257,NA())
A258: Chihuido de la Sierra Negra | B258: 2006-11 | C258: 88013.4 | D258: 1117644.9 | E258: =E257+C258 | F258: =IF(C258>0,D258/C258,NA())
A259: Chihuido de la Sierra Negra | B259: 2006-12 | C259: 93731.2 | D259: 1152837.3 | E259: =E258+C259 | F259: =IF(C259>0,D259/C259,NA())
A260: Chihuido de la Sierra Negra | B260: 2007-01 | C260: 90578.2 | D260: 1179444.8 | E260: =E259+C260 | F260: =IF(C260>0,D260/C260,NA())
... A494: Chihuido de la Sierra Negra | B494: 2026-07 | C494: 12046.4 | D494: 409192.7 | E494: =E493+C494 | F494: =IF(C494>0,D494/C494,NA())
A495: El Trapial | B495: 2006-01 | C495: 206192 | D495: 1562668 | E495: =C495 | F495: =IF(C495>0,D495/C495,NA())
A496: El Trapial | B496: 2006-02 | C496: 183596 | D496: 1433495 | E496: =E495+C496 | F496: =IF(C496>0,D496/C496,NA())
A497: El Trapial | B497: 2006-03 | C497: 201610 | D497: 1584979.1 | E497: =E496+C497 | F497: =IF(C497>0,D497/C497,NA())
A498: El Trapial | B498: 2006-04 | C498: 188397 | D498: 1526877.7 | E498: =E497+C498 | F498: =IF(C498>0,D498/C498,NA())
A499: El Trapial | B499: 2006-05 | C499: 199095 | D499: 1626278 | E499: =E498+C499 | F499: =IF(C499>0,D499/C499,NA())
A500: El Trapial | B500: 2006-06 | C500: 196197 | D500: 1515860 | E500: =E499+C500 | F500: =IF(C500>0,D500/C500,NA())
A501: El Trapial | B501: 2006-07 | C501: 203451 | D501: 1584866 | E501: =E500+C501 | F501: =IF(C501>0,D501/C501,NA())
A502: El Trapial | B502: 2006-08 | C502: 206926 | D502: 1627684 | E502: =E501+C502 | F502: =IF(C502>0,D502/C502,NA())
A503: El Trapial | B503: 2006-09 | C503: 200266 | D503: 1596615 | E503: =E502+C503 | F503: =IF(C503>0,D503/C503,NA())
A504: El Trapial | B504: 2006-10 | C504: 209132 | D504: 1625232 | E504: =E503+C504 | F504: =IF(C504>0,D504/C504,NA())
A505: El Trapial | B505: 2006-11 | C505: 191434 | D505: 1515170 | E505: =E504+C505 | F505: =IF(C505>0,D505/C505,NA())
...
